Workbook

Sheet README
A1: AI True Cost Model
A3: Purpose
A4: Estimates the all-in cost per million output tokens for a frontier AI model, broken into FIVE cost layers including capex, and compares against typical subscription and contract revenue. Also includes a three-way competitive comparison (Google / OpenAI / Anthropic) before and after the April/May 2026 Anthropic compute deals.
A8: Sheets
A9: 1. Assumptions | B9: All inputs in blue. Edit these to flex the model. Three scenarios: Low / Mid / High.
A10: 2. Cost Build | B10: Calculates cost per million output tokens across five layers including capex.
A11: 3. Revenue Build | B11: Models blended revenue from consumer subs, API, enterprise, and government.
A12: 4. Unit Economics | B12: Compares cost vs revenue per query, per million tokens, and company-wide.
A13: 5. Sensitivity | B13: Single-variable sensitivity of cost per M tokens to key drivers.
A14: 6. Build vs Rent | B14: Toggles capex ownership mix between owned datacenter and rented hyperscaler capacity.
A15: 7. Breakeven | B15: Inverts cost into revenue and scale required to clear the cost stack.
A16: 8. No-Subsidy Pricing | B16: Consumer subscription cost at full-economic per usage tier.
A17: 9. Implicit Demand | B17: Token volume implied by committed multi-year compute spend per lab.
A18: 10. Plausibility | B18: Three lenses on whether the implied demand can be absorbed.
A19: 11. Capex Perspective | B19: Capex framed against US GDP, business investment, and grid capacity.
A20: 12. Stacks - Pre Announcement | B20: Three-way competitor comparison before the April/May 2026 deals.
A21: 13. Stacks - Post Announcement | B21: Updated comparison after Anthropic's Google/xAI/Amazon expansions.
A23: Color Convention
A24: Blue | B24: Hardcoded inputs you can change
A25: Black | B25: Formulas and calculations
A26: Green | B26: Cross-sheet references
A27: Yellow fill | B27: Key assumptions to review
A29: Caveats
A30: • Frontier lab cost structures are not public. All inputs are triangulated estimates as of early 2026.
A31: • Capex commitments often live in hyperscaler partners' balance sheets via take-or-pay contracts. The Build vs Rent toggle approximates how this allocates.
A32: • Inference cost per token has fallen roughly 10x year over year for comparable capability. Treat training amortization as the most volatile input.
A33: • Enterprise contract economics vary widely between deals.
A34: • The competitor stacks sheets reflect a specific view of relative cost positions; multipliers are editable.
A35: • Implicit Demand and Plausibility sheets translate dollars committed into tokens served at current cost - they are scenarios, not forecasts.

Sheet Assumptions
A1: Assumptions
A3: Driver | B3: Unit | C3: Low | D3: Mid | E3: High
A4: Layer 1: Training Amortization
A5: Frontier training run cost | B5: $M | C5: 100 | D5: 500 | E5: 1500
A6: Useful life of model | B6: months | C6: 24 | D6: 18 | E6: 12
A7: Trailing 12mo output tokens served (industry) | B7: trillions | C7: 500 | D7: 250 | E7: 100
A8: Lab share of those tokens | B8: % | C8: 0.3 | D8: 0.2 | E8: 0.1
A10: Layer 2: Inference Compute
A11: GPU cost per hour - RENTED (hyperscaler markup) | B11: $/hr | C11: 1.5 | D11: 2.5 | E11: 4
A12: GPU cost per hour - OWNED (operating only, no capex) | B12: $/hr | C12: 0.6 | D12: 1 | E12: 1.6
A13: Output tokens per GPU-hour | B13: tokens/hr | C13: 1500000 | D13: 800000 | E13: 400000
A14: Input:Output token ratio | B14: ratio | C14: 5 | D14: 8 | E14: 12
A15: Input token cost factor vs output | B15: % | C15: 0.2 | D15: 0.25 | E15: 0.3
A17: Layer 3: Infrastructure Overhead (operating)
A18: Power as % of compute cost | B18: % | C18: 0.15 | D18: 0.25 | E18: 0.4
A19: Networking, cooling, redundancy | B19: % | C19: 0.08 | D19: 0.12 | E19: 0.18
A20: Datacenter real estate (lease) | B20: % | C20: 0.03 | D20: 0.05 | E20: 0.08
A22: Layer 4: R&D, People, Data
A23: Annual R&D spend | B23: $M | C23: 800 | D23: 1500 | E23: 3000
A24: Annual data acquisition and licensing | B24: $M | C24: 50 | D24: 200 | E24: 500
A25: RLHF and human feedback labor | B25: $M | C25: 30 | D25: 80 | E25: 200
A27: Layer 5: Capex (amortized)
A28: Datacenter capacity required | B28: MW | C28: 300 | D28: 1000 | E28: 3000
A29: Datacenter buildout cost | B29: $M/MW | C29: 25 | D29: 40 | E29: 60
A30: Datacenter useful life | B30: years | C30: 20 | D30: 15 | E30: 10
A31: GPU count required at scale | B31: thousands | C31: 200 | D31: 600 | E31: 1500
A32: Avg GPU system cost (all-in) | B32: $K | C32: 30 | D32: 50 | E32: 80
A33: GPU useful life before refresh | B33: years | C33: 5 | D33: 4 | E33: 3
A34: Power infra capex (substations, etc) | B34: $M | C34: 500 | D34: 2000 | E34: 6000
A35: Power infra useful life | B35: years | C35: 25 | D35: 20 | E35: 15
A36: % of capex owned vs rented (0=all rent, 100=all own) | B36: % | C36: 0 | D36: 0.5 | E36: 1
A38: Revenue Inputs
A39: Consumer paid subscribers | B39: millions | C39: 5 | D39: 15 | E39: 30
A40: Avg consumer subscription price | B40: $/mo | C40: 18 | D40: 20 | E40: 22
A41: Avg consumer queries per user per month | B41: queries | C41: 100 | D41: 250 | E41: 500
A42: Avg output tokens per consumer query | B42: tokens | C42: 400 | D42: 600 | E42: 1000
A43: API revenue (annual) | B43: $M | C43: 200 | D43: 600 | E43: 1500
A44: Enterprise contract revenue (annual) | B44: $M | C44: 500 | D44: 2000 | E44: 5000
A45: Government contract revenue (annual) | B45: $M | C45: 50 | D45: 250 | E45: 800
A47: Demand and Breakeven Inputs
...

Sheet Cost Build
A1: Cost Per Million Output Tokens
A2: Includes Layer 5 capex. Build-vs-rent mix is set in Assumptions (capex_ownership_pct).
A4: Component | B4: Formula Logic | C4: Low | D4: Mid | E4: High
A5: Layer 1: Training amortization
A6: Training cost ($M) | C6: =Assumptions!C5 | D6: =Assumptions!D5 | E6: =Assumptions!E5
A7: Useful life (months) | C7: =Assumptions!C6 | D7: =Assumptions!D6 | E7: =Assumptions!E6
A8: Lab tokens annually (trillions) | B8: Industry tokens x lab share | C8: =Assumptions!C7*Assumptions!C8 | D8: =Assumptions!D7*Assumptions!D8 | E8: =Assumptions!E7*Assumptions!E8
A9: $/M output tokens (training) | B9: Training$ / (lab tokens x life/12) | C9: =C6/(C8*C7/12) | D9: =D6/(D8*D7/12) | E9: =E6/(E8*E7/12)
A11: Layer 2: Inference compute
A12: Effective GPU $/hr (blended own/rent) | B12: own_pct x owned_rate + (1-own_pct) x rented_rate | C12: =Assumptions!C36*Assumptions!C12+(1-Assumptions!C36)*Assumptions!C11 | D12: =Assumptions!D36*Assumptions!D12+(1-Assumptions!D36)*Assumptions!D11 | E12: =Assumptions!E36*Assumptions!E12+(1-Assumptions!E36)*Assumptions!E11
A13: Output tokens per GPU-hr | C13: =Assumptions!C13 | D13: =Assumptions!D13 | E13: =Assumptions!E13
A14: Output compute $/M tokens | B14: GPU $/hr x 1M / tokens per hr | C14: =C12*1000000/C13 | D14: =D12*1000000/D13 | E14: =E12*1000000/E13
A15: Input compute $/M tokens | B15: Output compute x ratio x cost factor | C15: =C14*Assumptions!C14*Assumptions!C15 | D15: =D14*Assumptions!D14*Assumptions!D15 | E15: =E14*Assumptions!E14*Assumptions!E15
A16: $/M output tokens (inference) | C16: =C14+C15 | D16: =D14+D15 | E16: =E14+E15
A18: Layer 3: Infrastructure overhead (operating)
A19: Power overhead | C19: =C16*Assumptions!C18 | D19: =D16*Assumptions!D18 | E19: =E16*Assumptions!E18
A20: Networking, cooling, redundancy | C20: =C16*Assumptions!C19 | D20: =D16*Assumptions!D19 | E20: =E16*Assumptions!E19
A21: Datacenter real estate (lease) | C21: =C16*Assumptions!C20 | D21: =D16*Assumptions!D20 | E21: =E16*Assumptions!E20
A22: $/M output tokens (infra) | C22: =C19+C20+C21 | D22: =D19+D20+D21 | E22: =E19+E20+E21
A24: Layer 4: R&D, people, data
A25: Annual R&D + data + RLHF ($M) | C25: =Assumptions!C23+Assumptions!C24+Assumptions!C25 | D25: =Assumptions!D23+Assumptions!D24+Assumptions!D25 | E25: =Assumptions!E23+Assumptions!E24+Assumptions!E25
A26: $/M output tokens (R&D) | B26: R&D$ / annual lab tokens | C26: =C25/C8 | D26: =D25/D8 | E26: =E25/E8
A28: Layer 5: Capex amortization
A29: Datacenter capex total ($M) | B29: capacity_MW x cost_per_MW | C29: =Assumptions!C28*Assumptions!C29 | D29: =Assumptions!D28*Assumptions!D29 | E29: =Assumptions!E28*Assumptions!E29
A30: GPU capex total ($M) | B30: gpu_count(K) x unit_cost(K) | C30: =Assumptions!C31*Assumptions!C32 | D30: =Assumptions!D31*Assumptions!D32 | E30: =Assumptions!E31*Assumptions!E32
A31: Power infra capex ($M) | C31: =Assumptions!C34 | D31: =Assumptions!D34 | E31: =Assumptions!E34
A32: Annual depreciation ($M) | B32: DC/life + GPU/life + power_infra/life | C32: =C29/Assumptions!C30+C30/Assumptions!C33+C31/Assumptions!C35 | D32: =D29/Assumptions!D30+D30/Assumptions!D33+D31/Assumptions!D35 | E32: =E29/Assumptions!E30+E30/Assumptions!E33+E31/Assumptions!E35
A33: Capex burden borne by lab (own pct) | B33: Annual depr x ownership % | C33: =C32*Assumptions!C36 | D33: =D32*Assumptions!D36 | E33: =E32*Assumptions!E36
A34: $/M output tokens (capex - lab) | B34: Capex borne / lab annual tokens | C34: =C33/C8 | D34: =D33/D8 | E34: =E33/E8
A35: $/M output tokens (capex - in GPU rate, rented portion) | B35: Already inside Layer 2 via rented GPU markup | C35: =(Assumptions!C11-Assumptions!C12)*1000000/Assumptions!C13*(1-Assumptions!C36)*(1+Assumptions!C14*Assumptions!C15) | D35: =(Assumptions!D11-Assumptions!D12)*1000000/Assumptions!D13*(1-Assumptions!D36)*(1+Assumptions!D14*Assumptions!D15) | E35: =(Assumptions!E11-Assumptions!E12)*1000000/Assumptions!E13*(1-Assumptions!E36)*(1+Assumptions!E14*Assumptions!E15)
A36: $/M output tokens (capex TOTAL economic) | B36: Lab capex burden + rent markup (full economic cost) | C36: =C34+C35 | D36: =D34+D35 | E36: =E34+E35
A38: TOTAL TRUE COST per M output tokens | B38: Sum of layers 1-4 + capex borne by lab only | C38: =C9+C16+C22+C26+C34 | D38: =D9+D16+D22+D26+D34 | E38: =E9+E16+E22+E26+E34
A39: TOTAL ECONOMIC COST per M output tokens | B39: Includes capex borne by hyperscaler partners too | C39: =C9+(Assumptions!C12*1000000/Assumptions!C13*(1+Assumptions!C14*Assumptions!C15))+(Assumptions!C12*1000000/Assumptions!C13*(1+Assumptions!C14*Assumptions!C15))*(Assumptions!C18+Assumptions!C19+Assumptions!C20)+C26+C32/C8 | D39: =D9+(Assumptions!D12*1000000/Assumptions!D13*(1+Assumptions!D14*Assumptions!D15))+(Assumptions!D12*1000000/Assumptions!D13*(1+Assumptions!D14*Assumptions!D15))*(Assumptions!D18+Assumptions!D19+Assumptions!D20)+D26+D32/D8 | E39: =E9+(Assumptions!E12*1000000/Assumptions!E13*(1+Assumptions!E14*Assumptions!E15))+(Assumptions!E12*1000000/Assumptions!E13*(1+Assumptions!E14*Assumptions!E15))*(Assumptions!E18+Assumptions!E19+Assumptions!E20)+E26+E32/E8
A41: Layer share of total lab cash cost (Mid)
A42: Training % | D42: =D9/D38
A43: Inference % | D43: =D16/D38
A44: Infrastructure % | D44: =D22/D38
A45: R&D % | D45: =D26/D38
A46: Capex (lab borne) % | D46: =D34/D38

Sheet Revenue Build
A1: Revenue Build
A3: Component | B3: Formula Logic | C3: Low | D3: Mid | E3: High
A4: Consumer subscription revenue
A5: Paid subscribers (M) | C5: =Assumptions!C39 | D5: =Assumptions!D39 | E5: =Assumptions!E39
A6: Avg sub price ($/mo) | C6: =Assumptions!C40 | D6: =Assumptions!D40 | E6: =Assumptions!E40
A7: Annual consumer revenue ($M) | B7: Subs x price x 12 | C7: =C5*C6*12 | D7: =D5*D6*12 | E7: =E5*E6*12
A9: Consumer output tokens (annual, trillions) | B9: Subs x queries/mo x tokens/q x 12 | C9: =C5*1000000*Assumptions!C41*Assumptions!C42*12/1000000000000 | D9: =D5*1000000*Assumptions!D41*Assumptions!D42*12/1000000000000 | E9: =E5*1000000*Assumptions!E41*Assumptions!E42*12/1000000000000
A10: Consumer revenue per M output tokens | C10: =C7/C9 | D10: =D7/D9 | E10: =E7/E9
A12: API and contract revenue
A13: API revenue ($M) | C13: =Assumptions!C43 | D13: =Assumptions!D43 | E13: =Assumptions!E43
A14: Enterprise revenue ($M) | C14: =Assumptions!C44 | D14: =Assumptions!D44 | E14: =Assumptions!E44
A15: Government revenue ($M) | C15: =Assumptions!C45 | D15: =Assumptions!D45 | E15: =Assumptions!E45
A17: TOTAL annual revenue ($M) | C17: =C7+C13+C14+C15 | D17: =D7+D13+D14+D15 | E17: =E7+E13+E14+E15
A19: Revenue mix (Mid)
A20: Consumer % | D20: =D7/D17
A21: API % | D21: =D13/D17
A22: Enterprise % | D22: =D14/D17
A23: Government % | D23: =D15/D17

Sheet Unit Economics
A1: Unit Economics: Cost vs Revenue
A3: Metric | B3: Notes | C3: Low | D3: Mid | E3: High
A4: Cost per M tokens (lab cash) | B4: Capex borne by lab only | C4: ='Cost Build'!C38 | D4: ='Cost Build'!D38 | E4: ='Cost Build'!E38
A5: Cost per M tokens (full economic) | B5: Includes hyperscaler-borne capex | C5: ='Cost Build'!C39 | D5: ='Cost Build'!D39 | E5: ='Cost Build'!E39
A6: Consumer revenue per M tokens | C6: ='Revenue Build'!C10 | D6: ='Revenue Build'!D10 | E6: ='Revenue Build'!E10
A7: Consumer margin vs lab cash cost | C7: =IFERROR((C6-C4)/C6,0) | D7: =IFERROR((D6-D4)/D6,0) | E7: =IFERROR((E6-E4)/E6,0)
A8: Consumer margin vs full economic cost | C8: =IFERROR((C6-C5)/C6,0) | D8: =IFERROR((D6-D5)/D6,0) | E8: =IFERROR((E6-E5)/E6,0)
A10: Per-query view (consumer)
A11: Avg output tokens per query | C11: =Assumptions!C42 | D11: =Assumptions!D42 | E11: =Assumptions!E42
A12: Cost per query - lab cash ($) | C12: =C4*C11/1000000 | D12: =D4*D11/1000000 | E12: =E4*E11/1000000
A13: Cost per query - full economic ($) | C13: =C5*C11/1000000 | D13: =D5*D11/1000000 | E13: =E5*E11/1000000
A14: Revenue per query ($, consumer) | C14: =C6*C11/1000000 | D14: =D6*D11/1000000 | E14: =E6*E11/1000000
A15: Margin per query - lab cash ($) | C15: =C14-C12 | D15: =D14-D12 | E15: =E14-E12
A16: Margin per query - full economic ($) | C16: =C14-C13 | D16: =D14-D13 | E16: =E14-E13
A18: Company-wide view
A19: Total annual revenue ($M) | C19: ='Revenue Build'!C17 | D19: ='Revenue Build'!D17 | E19: ='Revenue Build'!E17
A20: Total annual cost - lab cash ($M) | C20: =C4*'Cost Build'!C8 | D20: =D4*'Cost Build'!D8 | E20: =E4*'Cost Build'!E8
A21: Total annual cost - full economic ($M) | C21: =C5*'Cost Build'!C8 | D21: =D5*'Cost Build'!D8 | E21: =E5*'Cost Build'!E8
A22: Operating margin - lab cash ($M) | C22: =C19-C20 | D22: =D19-D20 | E22: =E19-E20
A23: Operating margin - full economic ($M) | C23: =C19-C21 | D23: =D19-D21 | E23: =E19-E21
A24: Operating margin % - full economic | C24: =IFERROR((C19-C21)/C19,0) | D24: =IFERROR((D19-D21)/D19,0) | E24: =IFERROR((E19-E21)/E19,0)

Sheet Sensitivity
A1: Sensitivity: Cost per M Tokens (Mid base, lab cash basis)
A2: Each row varies one driver while holding others at Mid.
A4: Driver | B4: Direction | C4: -50% | D4: -25% | E4: Base (Mid) | F4: +25% | G4: +50%
A5: Training run cost | B5: Affects training layer | C5: ='Cost Build'!D38-'Cost Build'!D9+'Cost Build'!D9*0.5 | D5: ='Cost Build'!D38-'Cost Build'!D9+'Cost Build'!D9*0.75 | E5: ='Cost Build'!D38-'Cost Build'!D9+'Cost Build'!D9*1.0 | F5: ='Cost Build'!D38-'Cost Build'!D9+'Cost Build'!D9*1.25 | G5: ='Cost Build'!D38-'Cost Build'!D9+'Cost Build'!D9*1.5
A6: Lab annual tokens served | B6: Affects training, R&D, capex (inverse) | C6: ='Cost Build'!D38-'Cost Build'!D9-'Cost Build'!D26-'Cost Build'!D34+('Cost Build'!D9+'Cost Build'!D26+'Cost Build'!D34)/0.5 | D6: ='Cost Build'!D38-'Cost Build'!D9-'Cost Build'!D26-'Cost Build'!D34+('Cost Build'!D9+'Cost Build'!D26+'Cost Build'!D34)/0.75 | E6: ='Cost Build'!D38-'Cost Build'!D9-'Cost Build'!D26-'Cost Build'!D34+('Cost Build'!D9+'Cost Build'!D26+'Cost Build'!D34)/1.0 | F6: ='Cost Build'!D38-'Cost Build'!D9-'Cost Build'!D26-'Cost Build'!D34+('Cost Build'!D9+'Cost Build'!D26+'Cost Build'!D34)/1.25 | G6: ='Cost Build'!D38-'Cost Build'!D9-'Cost Build'!D26-'Cost Build'!D34+('Cost Build'!D9+'Cost Build'!D26+'Cost Build'!D34)/1.5
A7: GPU $/hr | B7: Affects inference + infra | C7: ='Cost Build'!D38-'Cost Build'!D16-'Cost Build'!D22+('Cost Build'!D16+'Cost Build'!D22)*0.5 | D7: ='Cost Build'!D38-'Cost Build'!D16-'Cost Build'!D22+('Cost Build'!D16+'Cost Build'!D22)*0.75 | E7: ='Cost Build'!D38-'Cost Build'!D16-'Cost Build'!D22+('Cost Build'!D16+'Cost Build'!D22)*1.0 | F7: ='Cost Build'!D38-'Cost Build'!D16-'Cost Build'!D22+('Cost Build'!D16+'Cost Build'!D22)*1.25 | G7: ='Cost Build'!D38-'Cost Build'!D16-'Cost Build'!D22+('Cost Build'!D16+'Cost Build'!D22)*1.5
A8: Tokens per GPU-hr | B8: Inference efficiency (inverse) | C8: ='Cost Build'!D38-'Cost Build'!D16-'Cost Build'!D22+('Cost Build'!D16+'Cost Build'!D22)/0.5 | D8: ='Cost Build'!D38-'Cost Build'!D16-'Cost Build'!D22+('Cost Build'!D16+'Cost Build'!D22)/0.75 | E8: ='Cost Build'!D38-'Cost Build'!D16-'Cost Build'!D22+('Cost Build'!D16+'Cost Build'!D22)/1.0 | F8: ='Cost Build'!D38-'Cost Build'!D16-'Cost Build'!D22+('Cost Build'!D16+'Cost Build'!D22)/1.25 | G8: ='Cost Build'!D38-'Cost Build'!D16-'Cost Build'!D22+('Cost Build'!D16+'Cost Build'!D22)/1.5
A9: Annual R&D spend | B9: Affects R&D layer | C9: ='Cost Build'!D38-'Cost Build'!D26+'Cost Build'!D26*0.5 | D9: ='Cost Build'!D38-'Cost Build'!D26+'Cost Build'!D26*0.75 | E9: ='Cost Build'!D38-'Cost Build'!D26+'Cost Build'!D26*1.0 | F9: ='Cost Build'!D38-'Cost Build'!D26+'Cost Build'!D26*1.25 | G9: ='Cost Build'!D38-'Cost Build'!D26+'Cost Build'!D26*1.5
A10: Useful life of model | B10: Longer life = more amortization base | C10: ='Cost Build'!D38-'Cost Build'!D9+'Cost Build'!D9/0.5 | D10: ='Cost Build'!D38-'Cost Build'!D9+'Cost Build'!D9/0.75 | E10: ='Cost Build'!D38-'Cost Build'!D9+'Cost Build'!D9/1.0 | F10: ='Cost Build'!D38-'Cost Build'!D9+'Cost Build'!D9/1.25 | G10: ='Cost Build'!D38-'Cost Build'!D9+'Cost Build'!D9/1.5
A11: Datacenter capacity (MW) | B11: Affects capex layer | C11: ='Cost Build'!D38-'Cost Build'!D34+'Cost Build'!D34*0.5 | D11: ='Cost Build'!D38-'Cost Build'!D34+'Cost Build'!D34*0.75 | E11: ='Cost Build'!D38-'Cost Build'!D34+'Cost Build'!D34*1.0 | F11: ='Cost Build'!D38-'Cost Build'!D34+'Cost Build'!D34*1.25 | G11: ='Cost Build'!D38-'Cost Build'!D34+'Cost Build'!D34*1.5
A12: GPU count | B12: Affects capex layer | C12: ='Cost Build'!D38-'Cost Build'!D34+'Cost Build'!D34*0.5 | D12: ='Cost Build'!D38-'Cost Build'!D34+'Cost Build'!D34*0.75 | E12: ='Cost Build'!D38-'Cost Build'!D34+'Cost Build'!D34*1.0 | F12: ='Cost Build'!D38-'Cost Build'!D34+'Cost Build'!D34*1.25 | G12: ='Cost Build'!D38-'Cost Build'!D34+'Cost Build'!D34*1.5
A13: Capex ownership % | B13: See Build vs Rent sheet for full toggle | C13: See Build vs Rent sheet | D13: See Build vs Rent sheet | E13: See Build vs Rent sheet | F13: See Build vs Rent sheet | G13: See Build vs Rent sheet
A15: Read: which lever moves cost most?
A16: • If a row's spread is wide, that driver dominates true cost.
A17: • Lab annual tokens now affects three layers (training, R&D, capex) so it is the most leveraged driver.
A18: • Capex layer makes datacenter capacity and GPU count first-order drivers, not rounding errors.

Sheet Build vs Rent
A1: Build vs Rent: Capex Allocation Toggle
A2: Shows total cost per M tokens at different ownership mixes. Base case uses Mid scenario assumptions.
A4: Key insight
A5: Building your own datacenter front-loads capex but lowers ongoing inference cost. Renting from hyperscalers shifts capex burden to them, but they pass it through as higher GPU $/hr. Total ECONOMIC cost should be similar across mixes — it's a question of who carries the risk and balance sheet.
A9: Ownership % | B9: 0% (all rent) | C9: 25% | D9: 50% (mixed) | E9: 75% | F9: 100% (all own)
A10: Effective GPU $/hr | B10: =0.0*Assumptions!D12+(1-0.0)*Assumptions!D11 | C10: =0.25*Assumptions!D12+(1-0.25)*Assumptions!D11 | D10: =0.5*Assumptions!D12+(1-0.5)*Assumptions!D11 | E10: =0.75*Assumptions!D12+(1-0.75)*Assumptions!D11 | F10: =1.0*Assumptions!D12+(1-1.0)*Assumptions!D11
A11: Inference $/M tokens (output+input) | B11: =B10*1000000/Assumptions!D13*(1+Assumptions!D14*Assumptions!D15) | C11: =C10*1000000/Assumptions!D13*(1+Assumptions!D14*Assumptions!D15) | D11: =D10*1000000/Assumptions!D13*(1+Assumptions!D14*Assumptions!D15) | E11: =E10*1000000/Assumptions!D13*(1+Assumptions!D14*Assumptions!D15) | F11: =F10*1000000/Assumptions!D13*(1+Assumptions!D14*Assumptions!D15)
A12: Infra overhead $/M tokens | B12: =B11*(Assumptions!D18+Assumptions!D19+Assumptions!D20) | C12: =C11*(Assumptions!D18+Assumptions!D19+Assumptions!D20) | D12: =D11*(Assumptions!D18+Assumptions!D19+Assumptions!D20) | E12: =E11*(Assumptions!D18+Assumptions!D19+Assumptions!D20) | F12: =F11*(Assumptions!D18+Assumptions!D19+Assumptions!D20)
A13: Capex $/M tokens (lab cash) | B13: ='Cost Build'!D32*0.0/'Cost Build'!D8 | C13: ='Cost Build'!D32*0.25/'Cost Build'!D8 | D13: ='Cost Build'!D32*0.5/'Cost Build'!D8 | E13: ='Cost Build'!D32*0.75/'Cost Build'!D8 | F13: ='Cost Build'!D32*1.0/'Cost Build'!D8
A14: Training + R&D $/M tokens | B14: ='Cost Build'!D9+'Cost Build'!D26 | C14: ='Cost Build'!D9+'Cost Build'!D26 | D14: ='Cost Build'!D9+'Cost Build'!D26 | E14: ='Cost Build'!D9+'Cost Build'!D26 | F14: ='Cost Build'!D9+'Cost Build'!D26
A15: TOTAL lab cash cost $/M tokens | B15: =B11+B12+B13+B14 | C15: =C11+C12+C13+C14 | D15: =D11+D12+D13+D14 | E15: =E11+E12+E13+E14 | F15: =F11+F12+F13+F14
A16: TOTAL economic cost $/M tokens | B16: =(Assumptions!D12*1000000/Assumptions!D13*(1+Assumptions!D14*Assumptions!D15))+(Assumptions!D12*1000000/Assumptions!D13*(1+Assumptions!D14*Assumptions!D15))*(Assumptions!D18+Assumptions!D19+Assumptions!D20)+'Cost Build'!D32/'Cost Build'!D8+'Cost Build'!D9+'Cost Build'!D26 | C16: =(Assumptions!D12*1000000/Assumptions!D13*(1+Assumptions!D14*Assumptions!D15))+(Assumptions!D12*1000000/Assumptions!D13*(1+Assumptions!D14*Assumptions!D15))*(Assumptions!D18+Assumptions!D19+Assumptions!D20)+'Cost Build'!D32/'Cost Build'!D8+'Cost Build'!D9+'Cost Build'!D26 | D16: =(Assumptions!D12*1000000/Assumptions!D13*(1+Assumptions!D14*Assumptions!D15))+(Assumptions!D12*1000000/Assumptions!D13*(1+Assumptions!D14*Assumptions!D15))*(Assumptions!D18+Assumptions!D19+Assumptions!D20)+'Cost Build'!D32/'Cost Build'!D8+'Cost Build'!D9+'Cost Build'!D26 | E16: =(Assumptions!D12*1000000/Assumptions!D13*(1+Assumptions!D14*Assumptions!D15))+(Assumptions!D12*1000000/Assumptions!D13*(1+Assumptions!D14*Assumptions!D15))*(Assumptions!D18+Assumptions!D19+Assumptions!D20)+'Cost Build'!D32/'Cost Build'!D8+'Cost Build'!D9+'Cost Build'!D26 | F16: =(Assumptions!D12*1000000/Assumptions!D13*(1+Assumptions!D14*Assumptions!D15))+(Assumptions!D12*1000000/Assumptions!D13*(1+Assumptions!D14*Assumptions!D15))*(Assumptions!D18+Assumptions!D19+Assumptions!D20)+'Cost Build'!D32/'Cost Build'!D8+'Cost Build'!D9+'Cost Build'!D26 | G16: (Should be ~constant across mixes)
A18: Capex burden split
A19: Annual depreciation TOTAL ($M) | B19: ='Cost Build'!D32 | C19: ='Cost Build'!D32 | D19: ='Cost Build'!D32 | E19: ='Cost Build'!D32 | F19: ='Cost Build'!D32
A20: Borne by lab ($M/yr) | B20: ='Cost Build'!D32*0.0 | C20: ='Cost Build'!D32*0.25 | D20: ='Cost Build'!D32*0.5 | E20: ='Cost Build'!D32*0.75 | F20: ='Cost Build'!D32*1.0
A21: Borne by hyperscaler ($M/yr) | B21: ='Cost Build'!D32*(1-0.0) | C21: ='Cost Build'!D32*(1-0.25) | D21: ='Cost Build'!D32*(1-0.5) | E21: ='Cost Build'!D32*(1-0.75) | F21: ='Cost Build'!D32*(1-1.0)
A22: Total capex commitment, undepreciated ($B) | B22: =('Cost Build'!D29+'Cost Build'!D30+'Cost Build'!D31)/1000
A24: What this means
A25: • At 0% ownership: Lab pays only for tokens consumed via rental rates. Hyperscaler bears full capex risk.
A26: • At 100% ownership: Lab takes all capex on its own balance sheet, pays only operating costs in inference.
A27: • The Total ECONOMIC cost row should be roughly constant (orange row). What changes is WHO carries the risk.
A28: • Take-or-pay contracts effectively make 'rent' look like 'own' from a risk perspective even though it sits off-balance-sheet.
A29: • Capex is the elephant in the room: total commitment is far larger than any single year's revenue.

Sheet Breakeven
A1: Breakeven at Current Cost Structure
A2: Inverts the model: at the current full-economic cost per million tokens, what revenue mix and scale would clear the cost stack?
A4: Metric | B4: Notes | C4: Low | D4: Mid | E4: High
A5: A. Breakeven price per million tokens
A6: Full-economic cost per M tokens | B6: Margin-neutral price target | C6: ='Cost Build'!C39 | D6: ='Cost Build'!D39 | E6: ='Cost Build'!E39
A7: Current blended consumer yield per M tokens | B7: From Revenue Build | C7: ='Revenue Build'!C10 | D7: ='Revenue Build'!D10 | E7: ='Revenue Build'!E10
A8: Implicit subsidy per M tokens | B8: Cost minus consumer yield | C8: =C6-C7 | D8: =D6-D7 | E8: =E6-E7
A9: Required price multiple over current yield | C9: =IFERROR(C6/C7,0) | D9: =IFERROR(D6/D7,0) | E9: =IFERROR(E6/E7,0)
A11: B. Annual token volume needed at current revenue mix
A12: Current total revenue ($M) | C12: ='Revenue Build'!C17 | D12: ='Revenue Build'!D17 | E12: ='Revenue Build'!E17
A13: Lab tokens served today (trillions/yr) | C13: ='Cost Build'!C8 | D13: ='Cost Build'!D8 | E13: ='Cost Build'!E8
A14: Tokens needed to clear cost at today's revenue (T/yr) | B14: Rev$ / cost per M = M-token-units; div 1M for trillions | C14: =IFERROR(C12/C6,0) | D14: =IFERROR(D12/D6,0) | E14: =IFERROR(E12/E6,0)
A15: Revenue coverage of today's volume | B15: needed / served today (>100% = overfunded, <100% = revenue gap) | C15: =IFERROR(C14/C13,0) | D15: =IFERROR(D14/D13,0) | E15: =IFERROR(E14/E13,0)
A16: Revenue gap on today's volume (T tokens/yr unfunded) | B16: served today - tokens revenue can clear | C16: =C13-C14 | D16: =D13-D14 | E16: =E13-E14
A18: C. Trade-off grid: revenue per M tokens vs annual revenue ($B), Mid cost basis
A19: Tokens needed (trillions/yr) to clear full-economic cost
A20: $/M tokens | B20: $5B/yr | C20: $20B/yr | D20: $50B/yr | E20: $100B/yr | F20: $250B/yr
A21: $20 | B21: =5000/20 | C21: =20000/20 | D21: =50000/20 | E21: =100000/20 | F21: =250000/20
A22: $50 | B22: =5000/50 | C22: =20000/50 | D22: =50000/50 | E22: =100000/50 | F22: =250000/50
A23: $100 | B23: =5000/100 | C23: =20000/100 | D23: =50000/100 | E23: =100000/100 | F23: =250000/100
A24: $150 | B24: =5000/150 | C24: =20000/150 | D24: =50000/150 | E24: =100000/150 | F24: =250000/150
A25: $253 | B25: =5000/253 | C25: =20000/253 | D25: =50000/253 | E25: =100000/253 | F25: =250000/253
A26: $400 | B26: =5000/400 | C26: =20000/400 | D26: =50000/400 | E26: =100000/400 | F26: =250000/400
A28: Reading: at $50/M and $20B annual revenue target, the lab must serve 400T tokens/yr.

Sheet No-Subsidy Pricing
A1: No-Subsidy Consumer Subscription Pricing
A2: What a subscription would cost if priced at full-economic cost. Median tier ties to Assumptions queries_pm and tokens_per_q.
A4: Usage tier | B4: Driver | C4: Low | D4: Mid | E4: High
A5: Light tier
A6: Queries per month | C6: =Assumptions!C48 | D6: =Assumptions!D48 | E6: =Assumptions!E48
A7: Output tokens per query | C7: =Assumptions!C49 | D7: =Assumptions!D49 | E7: =Assumptions!E49
A8: Monthly output tokens | B8: queries x tokens/q | C8: =C6*C7 | D8: =D6*D7 | E8: =E6*E7
A9: Monthly cost at full-economic ($/mo) | B9: tokens x cost per M / 1M | C9: =C8*'Cost Build'!C39/1000000 | D9: =D8*'Cost Build'!D39/1000000 | E9: =E8*'Cost Build'!E39/1000000
A10: Current flat sub price ($/mo) | C10: =Assumptions!C40 | D10: =Assumptions!D40 | E10: =Assumptions!E40
A11: Implicit monthly subsidy ($/mo) | B11: cost minus flat price | C11: =C9-C10 | D11: =D9-D10 | E11: =E9-E10
A12: Effective $/M revenue at flat rate | B12: flat price x 1M / monthly tokens | C12: =IFERROR(C10*1000000/C8,0) | D12: =IFERROR(D10*1000000/D8,0) | E12: =IFERROR(E10*1000000/E8,0)
A14: Median tier
A15: Queries per month | C15: =Assumptions!C41 | D15: =Assumptions!D41 | E15: =Assumptions!E41
A16: Output tokens per query | C16: =Assumptions!C42 | D16: =Assumptions!D42 | E16: =Assumptions!E42
A17: Monthly output tokens | B17: queries x tokens/q | C17: =C15*C16 | D17: =D15*D16 | E17: =E15*E16
A18: Monthly cost at full-economic ($/mo) | B18: tokens x cost per M / 1M | C18: =C17*'Cost Build'!C39/1000000 | D18: =D17*'Cost Build'!D39/1000000 | E18: =E17*'Cost Build'!E39/1000000
A19: Current flat sub price ($/mo) | C19: =Assumptions!C40 | D19: =Assumptions!D40 | E19: =Assumptions!E40
A20: Implicit monthly subsidy ($/mo) | B20: cost minus flat price | C20: =C18-C19 | D20: =D18-D19 | E20: =E18-E19
A21: Effective $/M revenue at flat rate | B21: flat price x 1M / monthly tokens | C21: =IFERROR(C19*1000000/C17,0) | D21: =IFERROR(D19*1000000/D17,0) | E21: =IFERROR(E19*1000000/E17,0)
A23: Power tier
A24: Queries per month | C24: =Assumptions!C50 | D24: =Assumptions!D50 | E24: =Assumptions!E50
A25: Output tokens per query | C25: =Assumptions!C51 | D25: =Assumptions!D51 | E25: =Assumptions!E51
A26: Monthly output tokens | B26: queries x tokens/q | C26: =C24*C25 | D26: =D24*D25 | E26: =E24*E25
A27: Monthly cost at full-economic ($/mo) | B27: tokens x cost per M / 1M | C27: =C26*'Cost Build'!C39/1000000 | D27: =D26*'Cost Build'!D39/1000000 | E27: =E26*'Cost Build'!E39/1000000
A28: Current flat sub price ($/mo) | C28: =Assumptions!C40 | D28: =Assumptions!D40 | E28: =Assumptions!E40
A29: Implicit monthly subsidy ($/mo) | B29: cost minus flat price | C29: =C27-C28 | D29: =D27-D28 | E29: =E27-E28
A30: Effective $/M revenue at flat rate | B30: flat price x 1M / monthly tokens | C30: =IFERROR(C28*1000000/C26,0) | D30: =IFERROR(D28*1000000/D26,0) | E30: =IFERROR(E28*1000000/E26,0)
A32: • Light users (50 q/mo) effectively subsidize power users when everyone pays the same flat rate.
A33: • Median Mid cost-to-serve ($38/mo) is ~2x the current $20 flat rate.
A34: • Power users (2k q/mo, 1k-token outputs) cost ~25x the flat rate.
A35: • Implicit subsidy disappears only when (a) per-token cost falls 5-10x or (b) prices move to metered.

Sheet Implicit Demand
A1: Implicit Demand from Committed Compute Spend
A2: Inverts committed multi-year compute spend into the annual token volume it implies at current full-economic cost per million tokens.
A4: Lab | B4: Calc | C4: Low | D4: Mid | E4: High
A5: Anthropic
A6: 5-year commitment ($B) | C6: =Assumptions!C52 | D6: =Assumptions!D52 | E6: =Assumptions!E52
A7: Annual run rate ($B/yr) | B7: commitment / years | C7: =C6/Assumptions!C55 | D7: =D6/Assumptions!D55 | E7: =E6/Assumptions!E55
A8: Full-economic cost per M tokens ($) | C8: ='Cost Build'!C39 | D8: ='Cost Build'!D39 | E8: ='Cost Build'!E39
A9: Implied tokens served (T/yr) | B9: annual $B x 1000 / cost per M / 1M | C9: =IFERROR(C7*1000/C8,0) | D9: =IFERROR(D7*1000/D8,0) | E9: =IFERROR(E7*1000/E8,0)
A11: OpenAI
A12: 5-year commitment ($B) | C12: =Assumptions!C53 | D12: =Assumptions!D53 | E12: =Assumptions!E53
A13: Annual run rate ($B/yr) | B13: commitment / years | C13: =C12/Assumptions!C55 | D13: =D12/Assumptions!D55 | E13: =E12/Assumptions!E55
A14: Full-economic cost per M tokens ($) | C14: ='Cost Build'!C39 | D14: ='Cost Build'!D39 | E14: ='Cost Build'!E39
A15: Implied tokens served (T/yr) | B15: annual $B x 1000 / cost per M / 1M | C15: =IFERROR(C13*1000/C14,0) | D15: =IFERROR(D13*1000/D14,0) | E15: =IFERROR(E13*1000/E14,0)
A17: Baseline lab (xAI/Google/Meta avg)
A18: 5-year commitment ($B) | C18: =Assumptions!C54 | D18: =Assumptions!D54 | E18: =Assumptions!E54
A19: Annual run rate ($B/yr) | B19: commitment / years | C19: =C18/Assumptions!C55 | D19: =D18/Assumptions!D55 | E19: =E18/Assumptions!E55
A20: Full-economic cost per M tokens ($) | C20: ='Cost Build'!C39 | D20: ='Cost Build'!D39 | E20: ='Cost Build'!E39
A21: Implied tokens served (T/yr) | B21: annual $B x 1000 / cost per M / 1M | C21: =IFERROR(C19*1000/C20,0) | D21: =IFERROR(D19*1000/D20,0) | E21: =IFERROR(E19*1000/E20,0)
A23: Industry total
A24: Total 5-year commitment ($B) | C24: =C6+C12+C18 | D24: =D6+D12+D18 | E24: =E6+E12+E18
A25: Total annual run rate ($B/yr) | C25: =C7+C13+C19 | D25: =D7+D13+D19 | E25: =E7+E13+E19
A26: Total implied tokens (T/yr) | C26: =C9+C15+C21 | D26: =D9+D15+D21 | E26: =E9+E15+E21
A28: Industry tokens served today (T/yr) | C28: =Assumptions!C7 | D28: =Assumptions!D7 | E28: =Assumptions!E7
A29: Industry growth multiple implied | B29: implied / today | C29: =IFERROR(C26/C28,0) | D29: =IFERROR(D26/D28,0) | E29: =IFERROR(E26/E28,0)
A31: Outputs exported to Plausibility and Capex Perspective:

Sheet Plausibility
A1: Plausibility Check: Can Implied Demand Be Real?
A2: Three independent lenses on whether the token volumes implied by committed compute spend can plausibly be absorbed.
A4: Metric | B4: Calc | C4: Low | D4: Mid | E4: High
A5: Lens A: Heavy-user equivalents needed
A6: Industry implied tokens (T/yr) | C6: ='Implicit Demand'!C26 | D6: ='Implicit Demand'!D26 | E6: ='Implicit Demand'!E26
A7: Heavy user annual tokens (M/yr) | C7: =Assumptions!C56 | D7: =Assumptions!D56 | E7: =Assumptions!E56
A8: Heavy-user equivalents required (millions) | B8: T tokens / heavy user M tokens (T/M = millions) | C8: =IFERROR(C6/C7,0) | D8: =IFERROR(D6/D7,0) | E8: =IFERROR(E6/E7,0)
A10: Lens B: Enterprise seats implied
A11: Industry annual run rate ($B/yr) | C11: ='Implicit Demand'!C25 | D11: ='Implicit Demand'!D25 | E11: ='Implicit Demand'!E25
A12: Enterprise seat price ($/seat/yr) | C12: =Assumptions!C57 | D12: =Assumptions!D57 | E12: =Assumptions!E57
A13: Seats needed to fund commitments (millions) | B13: annual $B x 1B / seat price / 1M | C13: =IFERROR(C11*1000000000/C12/1000000,0) | D13: =IFERROR(D11*1000000000/D12/1000000,0) | E13: =IFERROR(E11*1000000000/E12/1000000,0)
A15: Lens C: Growth multiple vs today's industry
A16: Industry growth multiple implied | B16: from Implicit Demand | C16: ='Implicit Demand'!C29 | D16: ='Implicit Demand'!D29 | E16: ='Implicit Demand'!E29
A18: • Heavy-user equivalents in tens of millions imply ChatGPT-style mass adoption at higher per-user intensity than today.
A19: • Enterprise seats in tens of millions implies coverage well beyond today's enterprise SaaS footprint for any single category.
A20: • Growth multiples of 2-3x against a base that already grew 10x in the prior 18 months are what these commitments price in.

Sheet Capex Perspective
A1: Capex in Perspective
A2: Two views: a single lab's footprint, and the industry-wide footprint implied by committed multi-year spend.
A4: Metric | B4: Calc | C4: Low | D4: Mid | E4: High
A5: View A: Per-lab footprint (one frontier lab)
A6: One-time capex total ($M) | B6: DC + GPU + power infra | C6: ='Cost Build'!C29+'Cost Build'!C30+'Cost Build'!C31 | D6: ='Cost Build'!D29+'Cost Build'!D30+'Cost Build'!D31 | E6: ='Cost Build'!E29+'Cost Build'!E30+'Cost Build'!E31
A7: Annual depreciation ($M) | C7: ='Cost Build'!C32 | D7: ='Cost Build'!D32 | E7: ='Cost Build'!E32
A8: Datacenter capacity (MW) | C8: =Assumptions!C28 | D8: =Assumptions!D28 | E8: =Assumptions!E28
A10: Capex total as bps of US GDP | B10: capex $M / (GDP $T x 1M) x 10000 | C10: =IFERROR(C6/(Assumptions!C60*1000000)*10000,0) | D10: =IFERROR(D6/(Assumptions!D60*1000000)*10000,0) | E10: =IFERROR(E6/(Assumptions!E60*1000000)*10000,0)
A11: Annual depreciation as % of US business capex | B11: depr $M / (business capex $T x 1M) | C11: =IFERROR(C7/(Assumptions!C61*1000000),0) | D11: =IFERROR(D7/(Assumptions!D61*1000000),0) | E11: =IFERROR(E7/(Assumptions!E61*1000000),0)
A12: DC capacity as % of US grid peak demand | B12: DC MW / (grid GW x 1000) | C12: =IFERROR(C8/(Assumptions!C62*1000),0) | D12: =IFERROR(D8/(Assumptions!D62*1000),0) | E12: =IFERROR(E8/(Assumptions!E62*1000),0)
A13: Annual depreciation per US household ($/yr) | B13: depr $M / households (M) = $/household/yr | C13: =IFERROR(C7/Assumptions!C63,0) | D13: =IFERROR(D7/Assumptions!D63,0) | E13: =IFERROR(E7/Assumptions!E63,0)
A15: View B: Industry-wide footprint (5-year committed spend)
A16: (Anthropic + OpenAI + one baseline-lab proxy; not a literal industry total)
A17: Industry 5-year commitment ($B) | C17: ='Implicit Demand'!C24 | D17: ='Implicit Demand'!D24 | E17: ='Implicit Demand'!E24
A18: Industry annual run rate ($B/yr) | C18: ='Implicit Demand'!C25 | D18: ='Implicit Demand'!D25 | E18: ='Implicit Demand'!E25
A20: Annual rate as % of US GDP | B20: annual $B / (GDP $T x 1000) | C20: =IFERROR(C18/(Assumptions!C60*1000),0) | D20: =IFERROR(D18/(Assumptions!D60*1000),0) | E20: =IFERROR(E18/(Assumptions!E60*1000),0)
A21: Annual rate as % of US business capex | B21: annual $B / (business capex $T x 1000) | C21: =IFERROR(C18/(Assumptions!C61*1000),0) | D21: =IFERROR(D18/(Assumptions!D61*1000),0) | E21: =IFERROR(E18/(Assumptions!E61*1000),0)
A23: Implied physical buildout
A24: Hardware share of committed spend | C24: =Assumptions!C64 | D24: =Assumptions!D64 | E24: =Assumptions!E64
A25: Implied industry hardware capex ($B/yr) | B25: annual rate x hardware share | C25: =C18*C24 | D25: =D18*D24 | E25: =E18*E24
A26: Implied annual DC MW added | B26: hardware $B x 1000 / DC cost per MW | C26: =IFERROR(C25*1000/Assumptions!C29,0) | D26: =IFERROR(D25*1000/Assumptions!D29,0) | E26: =IFERROR(E25*1000/Assumptions!E29,0)
A27: New DC MW as % of US grid peak | C27: =IFERROR(C26/(Assumptions!C62*1000),0) | D27: =IFERROR(D26/(Assumptions!D62*1000),0) | E27: =IFERROR(E26/(Assumptions!E62*1000),0)
A29: • Per-lab capex of $30-50B is bps-level vs US GDP but a single-digit % of total US business investment.
A30: • Industry annual run rate at Mid (~$120B/yr) is roughly 0.4% of US GDP - measurable but not implausible at the macro level.
A31: • Physical constraint is grid capacity: implied new DC builds approach single-digit % of US peak demand annually.
A32: • The macro test isn't 'can the economy afford it' - it's 'can power/grid/permitting absorb it on this schedule.'

Sheet Stacks - Pre Announcement
A1: PRE-ANNOUNCEMENT (early 2026): Anthropic modeled as Amazon-stack proxy. See Stacks - Post Announcement for updated framing after the April/May 2026 Anthropic compute deals (Google $40B + TPUs, xAI Colossus 1, expanded Amazon).
A2: Three-Way Competitive Cost Comparison
A3: Multipliers applied to Mid scenario base cost. 1.0x = baseline lab cost. <1.0x = cost advantage. >1.0x = cost disadvantage.
A5: The three vertical stacks
A6: Google | B6: Search/Ads -> TPUs -> Datacenters -> Gemini -> Workspace/Android/Search distribution
A7: Microsoft + OpenAI | B7: Azure -> Nvidia GPUs -> Datacenters -> GPT -> Office/Windows/GitHub distribution
A8: Amazon + Anthropic | B8: AWS -> Trainium/Nvidia -> Datacenters -> Claude -> AWS Bedrock distribution
A10: Cost layer multipliers vs baseline lab (editable - blue cells)
A11: Cost Layer | B11: Google | C11: MSFT+OpenAI | D11: Amazon+Anthropic | E11: Notes
A12: Training cost | B12: 1 | C12: 1 | D12: 1 | E12: Roughly comparable across labs at the frontier
A13: Inference compute (silicon) | B13: 0.55 | C13: 1 | D13: 0.85 | E13: Google: TPU vs Nvidia 70% margin. Anthropic: some Trainium offset. OpenAI: pays full Nvidia tax.
A14: Infrastructure overhead | B14: 0.65 | C14: 1 | D14: 0.95 | E14: Google has 25 yrs of hyperscale ops experience. MSFT/AWS catching up but trail.
A15: R&D / people / data | B15: 0.85 | C15: 1 | D15: 1 | E15: Google has captive data (Search/YouTube). All have similar talent costs.
A16: Capex (effective burden) | B16: 0.7 | C16: 1 | D16: 1 | E16: Google self-funds from $90B+ cash flow. MSFT/Amazon also strong but capex is dedicated AI buildout.
A17: Distribution / CAC | B17: 0.3 | C17: 0.6 | D17: 0.6 | E17: Google: zero CAC via Search/Workspace. MSFT/Amazon: leverage existing enterprise relationships.
A18: (Distribution shown for reference - it affects revenue side, not the cost layers we sum below)
A20: Resulting cost per M tokens (Mid scenario, 50% capex ownership)
A21: Cost Layer | B21: Baseline lab | C21: Google | D21: MSFT+OpenAI | E21: Amazon+Anthropic
A22: Training | B22: ='Cost Build'!D9 | C22: ='Cost Build'!D9*B12 | D22: ='Cost Build'!D9*C12 | E22: ='Cost Build'!D9*D12
A23: Inference compute | B23: ='Cost Build'!D16 | C23: ='Cost Build'!D16*B13 | D23: ='Cost Build'!D16*C13 | E23: ='Cost Build'!D16*D13
A24: Infrastructure | B24: ='Cost Build'!D22 | C24: ='Cost Build'!D22*B14 | D24: ='Cost Build'!D22*C14 | E24: ='Cost Build'!D22*D14
A25: R&D / people / data | B25: ='Cost Build'!D26 | C25: ='Cost Build'!D26*B15 | D25: ='Cost Build'!D26*C15 | E25: ='Cost Build'!D26*D15
A26: Capex (lab cash) | B26: ='Cost Build'!D34 | C26: ='Cost Build'!D34*B16 | D26: ='Cost Build'!D34*C16 | E26: ='Cost Build'!D34*D16
A27: TOTAL cost per M tokens (lab cash) | B27: =SUM(B22:B26) | C27: =SUM(C22:C26) | D27: =SUM(D22:D26) | E27: =SUM(E22:E26)
A28: Cost vs baseline (lower = advantage) | B28: 100% | C28: =C27/B27 | D28: =D27/B27 | E28: =E27/B27
A30: What this means in practice
A31: Scenario | B31: Google margin | C31: OpenAI margin | D31: Anthropic margin | E31: Implication
A32: Consumer subs (~$133/M revenue yield) | B32: =('Revenue Build'!D10-C27)/'Revenue Build'!D10 | C32: =('Revenue Build'!D10-D27)/'Revenue Build'!D10 | D32: =('Revenue Build'!D10-E27)/'Revenue Build'!D10 | E32: Google can price-cut consumer aggressively without losing money
A33: API at $30/M output (mid market) | B33: =(30-C27)/30 | C33: =(30-D27)/30 | D33: =(30-E27)/30 | E33: At commodity pricing, OpenAI/Anthropic likely lose money. Google barely positive.
A34: API at $75/M output (frontier premium) | B34: =(75-C27)/75 | C34: =(75-D27)/75 | D34: =(75-E27)/75 | E34: Premium pricing is where standalone labs survive - if they have differentiation
A36: Strategic takeaways
A37: • Google's structural cost advantage is real and probably permanent. Roughly 35-50% lower all-in cost per token.
A38: • MSFT+OpenAI and Amazon+Anthropic are competitive only by absorbing the cost gap into hyperscaler P&Ls. They cannot win as standalones.
A39: • At commodity API prices, only Google has clear positive margin. Standalone labs need premium positioning or scale subsidies.
A40: • Google's weakness: organizational and product execution. They've fumbled product launches before. The bull case for OpenAI/Anthropic is that capability differentiation outruns Google's cost advantage.
A41: • The three-way structure favors Google in steady state. The standalone labs need to win NOW - before commoditization kicks in - or accept structural subordination.
A42: • This explains why OpenAI is pushing so hard into consumer (ChatGPT, Atlas browser) and Anthropic into enterprise/code (Claude Code, Bedrock). Both are trying to escape pure API commodity competition.

Sheet Stacks - Post Announcement
A1: POST-ANNOUNCEMENT: Multi-Stack Competitive Reality (May 2026)
A2: Reflects: Anthropic-Google $40B+TPU deal (Apr 2026), Anthropic-xAI Colossus 1 deal (May 2026), Amazon expansion to ~$100B / 5GW Trainium. Anthropic now multi-stack across Trainium, TPU, and Nvidia.
A5: Revised competitive structure
A6: Google | B6: Vertically integrated AND major arms dealer. Sells TPU capacity to Anthropic at scale. Trades some moat for cloud revenue and TPU validation as Nvidia alternative.
A7: OpenAI (single-stack) | B7: Most strategically constrained: locked into Microsoft/Azure/Nvidia. Cannot capture TPU economics. Cannot dual-source. Largest revenue but narrowest supplier base.
A8: Anthropic (multi-stack) | B8: Runs on Trainium (AWS), TPU (Google), Nvidia (xAI/CoreWeave). Captures portion of TPU cost advantage via Google deal. Portfolio diversification as strategic moat.
A10: Updated cost layer multipliers vs baseline lab (post-announcement)
A11: Cost Layer | B11: Google | C11: OpenAI (MSFT) | D11: Anthropic (multi) | E11: Change vs pre-announcement
A12: Training cost | B12: 1 | C12: 1 | D12: 1 | E12: Unchanged - frontier training comparable across labs
A13: Inference compute (silicon) | B13: 0.55 | C13: 1 | D13: 0.72 | E13: Anthropic 0.85 -> 0.72: TPU access flows through partial cost advantage
A14: Infrastructure overhead | B14: 0.65 | C14: 1 | D14: 0.85 | E14: Anthropic 0.95 -> 0.85: TPU + Trainium + scale = better infra leverage
A15: R&D / people / data | B15: 0.85 | C15: 1 | D15: 1 | E15: Unchanged
A16: Capex (effective burden) | B16: 0.7 | C16: 1 | D16: 0.85 | E16: Anthropic 1.0 -> 0.85: multi-vendor sourcing reduces single-supplier markup
A17: Distribution / CAC | B17: 0.3 | C17: 0.55 | D17: 0.5 | E17: OpenAI 0.6 -> 0.55 (consumer scale). Anthropic 0.6 -> 0.5 (Bedrock+Vertex+Azure)
A18: (Distribution shown for reference - affects revenue side, not summed in cost total)
A20: Resulting cost per M tokens (Mid scenario, 50% capex ownership)
A21: Cost Layer | B21: Baseline lab | C21: Google | D21: OpenAI | E21: Anthropic
A22: Training | B22: ='Cost Build'!D9 | C22: ='Cost Build'!D9*B12 | D22: ='Cost Build'!D9*C12 | E22: ='Cost Build'!D9*D12
A23: Inference compute | B23: ='Cost Build'!D16 | C23: ='Cost Build'!D16*B13 | D23: ='Cost Build'!D16*C13 | E23: ='Cost Build'!D16*D13
A24: Infrastructure | B24: ='Cost Build'!D22 | C24: ='Cost Build'!D22*B14 | D24: ='Cost Build'!D22*C14 | E24: ='Cost Build'!D22*D14
A25: R&D / people / data | B25: ='Cost Build'!D26 | C25: ='Cost Build'!D26*B15 | D25: ='Cost Build'!D26*C15 | E25: ='Cost Build'!D26*D15
A26: Capex (lab cash) | B26: ='Cost Build'!D34 | C26: ='Cost Build'!D34*B16 | D26: ='Cost Build'!D34*C16 | E26: ='Cost Build'!D34*D16
A27: TOTAL cost per M tokens (lab cash) | B27: =SUM(B22:B26) | C27: =SUM(C22:C26) | D27: =SUM(D22:D26) | E27: =SUM(E22:E26)
A28: Cost vs baseline (lower = advantage) | B28: 100% | C28: =C27/B27 | D28: =D27/B27 | E28: =E27/B27
A30: Side-by-side: pre vs post announcement
A31: Metric | B31: Baseline lab | C31: Google | D31: OpenAI | E31: Anthropic
A32: Pre-announcement total $/M | B32: ='Stacks - Pre Announcement'!B27 | C32: ='Stacks - Pre Announcement'!C27 | D32: ='Stacks - Pre Announcement'!D27 | E32: ='Stacks - Pre Announcement'!E27
A33: Post-announcement total $/M | B33: =B27 | C33: =C27 | D33: =D27 | E33: =E27
A34: Change ($) | B34: =B33-B32 | C34: =C33-C32 | D34: =D33-D32 | E34: =E33-E32
A35: Change (%) | B35: =IFERROR((B33-B32)/B32,0) | C35: =IFERROR((C33-C32)/C32,0) | D35: =IFERROR((D33-D32)/D32,0) | E35: =IFERROR((E33-E32)/E32,0)
A37: Margin at different price points (post-announcement)
A38: Scenario | B38: Google margin | C38: OpenAI margin | D38: Anthropic margin | E38: Implication
A39: Consumer subs (~$133/M revenue yield) | B39: =('Revenue Build'!D10-C27)/'Revenue Build'!D10 | C39: =('Revenue Build'!D10-D27)/'Revenue Build'!D10 | D39: =('Revenue Build'!D10-E27)/'Revenue Build'!D10 | E39: Anthropic now closer to Google margin via TPU access
A40: API at $30/M output (mid market) | B40: =(30-C27)/30 | C40: =(30-D27)/30 | D40: =(30-E27)/30 | E40: Still loss-making for all at mid pricing - capex burden dominates
A41: API at $75/M output (frontier premium) | B41: =(75-C27)/75 | C41: =(75-D27)/75 | D41: =(75-E27)/75 | E41: Anthropic gap to Google narrowed but OpenAI now most disadvantaged
A43: Revised strategic takeaways
A44: • Anthropic's cost gap vs Google narrowed substantially. From ~99% of baseline (pre) to ~88% (post). Still disadvantaged vs Google but materially closer.
A45: • OpenAI now the most strategically constrained of the three: locked into Nvidia + Microsoft, cannot capture TPU economics, single-vendor risk on silicon.
A46: • Google's vertical integration moat is partially monetized - they sell TPU capacity to a competitor for cloud revenue. Smart short-term, dilutive long-term.
A47: • Multi-stack diversification has emerged as a real competitive strategy. Anthropic running on Trainium + TPU + Nvidia is a new pattern.
...
